NOTE TO SELF: 


I see 3 failing tests on my machine:

psutil.tests.test_contracts.TestFetchAllProcesses.test_all 

<details>
    <summary> see trace </summary>
    
    Traceback (most recent call last):
      File "/Users/olivertome/Desktop/dev/projects/oss/psutil/psutil/_psosx.py", line 346, in wrapper
        return fun(self, *args, **kwargs)
      File "/Users/olivertome/Desktop/dev/projects/oss/psutil/psutil/_psosx.py", line 404, in cmdline
        return cext.proc_cmdline(self.pid)
    ProcessLookupError: [Errno 3] assume no such process (originated from sysctl(KERN_PROCARGS2) -> EINVAL)

    During handling of the above exception, another exception occurred:

    Traceback (most recent call last):
      File "/Users/olivertome/Desktop/dev/projects/oss/psutil/psutil/tests/test_contracts.py", line 389, in proc_info
        info[fun_name] = fun()
      File "/Users/olivertome/Desktop/dev/projects/oss/psutil/psutil/__init__.py", line 686, in cmdline
        return self._proc.cmdline()
      File "/Users/olivertome/Desktop/dev/projects/oss/psutil/psutil/_psosx.py", line 351, in wrapper
        raise NoSuchProcess(self.pid, self._name)
    psutil.NoSuchProcess: process no longer exists (pid=1404, name='login')
    
</details>

psutil.tests.test_unicode.TestFSAPIsWithInvalidPath

<details>
    <summary> see trace </summary>

    Traceback (most recent call last):
      File "/Users/olivertome/Desktop/dev/projects/oss/psutil/psutil/tests/test_unicode.py", line 179, in setUpClass
        create_exe(cls.funky_name)
      File "/Users/olivertome/Desktop/dev/projects/oss/psutil/psutil/tests/__init__.py", line 859, in create_exe
        shutil.copyfile(PYTHON_EXE, outpath)
      File "/opt/homebrew/Cellar/python@3.10/3.10.11/Frameworks/Python.framework/Versions/3.10/lib/python3.10/shutil.py", line 256, in copyfile
        with open(dst, 'wb') as fdst:
    OSError: [Errno 92] Illegal byte sequence: '/private/var/folders/hm/y1b672p17sv_ww02x03q8hcm0000gn/T/@psutil-61554-icml95ikf\udcc0\udc80'

</details>

psutil.tests.test_posix.TestSystemAPIs.test_users_started

<details>
    <summary> see trace </summary>

    Traceback (most recent call last):
      File "/Users/olivertome/Desktop/dev/projects/oss/psutil/psutil/tests/__init__.py", line 723, in wrapper
        return fun(*args, **kwargs)
      File "/Users/olivertome/Desktop/dev/projects/oss/psutil/psutil/tests/test_posix.py", line 371, in test_users_started
        raise ValueError(
    ValueError: cannot interpret tstamp in who output
    olivertome       console       9 Apr 12:20  old       566
    olivertome       ttys000       9 Apr 12:21 00:05     1404
    olivertome       ttys001      18 Apr 18:12   .      59842

</details>
